<robot name="rover">

    <material name="blue">
        <color rgba="0 0 0.8 1"/>
    </material>
    <material name="red">
        <color rgba="0.8 0 0 1"/>
    </material>
    <material name="green">
        <color rgba="0 0.8 0 1"/>
    </material>
    <material name="purple">
        <color rgba="0.8 0 0.8 1"/>
    </material>

    <gazebo>
        <plugin name="gazebo_ros_control" filename="libgazebo_ros_control.so">
        </plugin>
    </gazebo>

	<!-- chassie -->
    <link name="base_link">
 	    <inertial>
            <origin xyz="0 0 0" rpy="0 0 0"/>
            <mass value="0.2" />
            <inertia ixx="0.0005726" ixy="0.0" ixz="0.0" iyy="0.0005726" iyz="0.0" izz="0.0002704"/>
        </inertial>
        <collision>
            <origin rpy="0.0 0 0" xyz="0 0 0"/>
            <geometry>
                <box size="1.1176 0.4064 0.127"/>
            </geometry>
        </collision>
        <visual>
            <origin rpy="0.0 0 0" xyz="0 0 0"/>
            <geometry>
                <box size="1.1176 0.4064 0.127"/>
            </geometry>
            <material name="red"/>
        </visual>
	</link>
    <gazebo reference="base_link">
        <kp>1000000.0</kp>
        <kd>1000000.0</kd>
        <mu1>10.0</mu1>
        <mu2>10.0</mu2>
        <material>Gazebo/Red</material>
    </gazebo>

    <!-- Antenna -->>
    <link name="antenna_link">
      <inertial>
        <origin xyz="0 0 0.5" rpy="0 0 0"/>
        <mass value="1"/>
        <inertia ixx="100"  ixy="0"  ixz="0" iyy="100" iyz="0" izz="100" />
      </inertial>
   
      <visual>
        <origin xyz="0 0.5588 0" rpy="0 0 0" />
        <geometry>
          <cylinder radius="0.0635" length="1.5748"/>
        </geometry>
        <material name="Cyan">
          <color rgba="0 1.0 1.0 1.0"/>
        </material>
      </visual>
   
      <collision>
        <origin xyz="0 0.5588 0" rpy="0 0 0" />
        <geometry>
          <cylinder radius="0.0635" length="1.5748"/>
        </geometry>
  </collision>
    </link>
    <gazebo reference="antenna_link">
        <mu1 value="200.0"/>
        <mu2 value="100.0"/>
        <kp value="10000000.0" />
        <kd value="1.0" />
        <material>Gazebo/Grey</material>
    </gazebo>
    <joint name="Chassie_antenna_link_Joint" type="continuous">
    	<parent link="base_link"/>
    	<child link="antenna_link"/>
        <origin xyz="0 0 0.096" rpy="0 0 0"/>
        <limit lower="0" upper="0" effort="10.0" velocity="8.94"/>
        <axis xyz="1 0 0"/>
	</joint>

    <!-- Leg_FR -->>
    <link name="Leg_FR">
      <inertial>
        <origin xyz="0 0 0.5" rpy="0 0 0"/>
        <mass value="1"/>
        <inertia ixx="100"  ixy="0"  ixz="0" iyy="100" iyz="0" izz="100" />
      </inertial>
   
      <visual>
        <origin xyz="0.5588 0.2032 0" rpy="0 0 0" />
        <geometry>
          <box size="0.3048 0.127 0.1143" />
        </geometry>
        <material name="Cyan">
          <color rgba="0 1.0 1.0 1.0"/>
        </material>
      </visual>
   
      <collision>
        <origin xyz="0.5588 0.2032 0" rpy="0 0 0" />
        <geometry>
          <box size="0.3048 0.127 0.1143" />
        </geometry>
  </collision>
    </link>
        <gazebo reference="Leg_FR">
        <mu1 value="200.0"/>
        <mu2 value="100.0"/>
        <kp value="10000000.0" />
        <kd value="1.0" />
        <material>Gazebo/Grey</material>
    </gazebo>
    <joint name="Chassie_Leg_FR_Joint" type="continuous">
    	<parent link="base_link"/>
    	<child link="Leg_FR"/>
        <origin xyz="0 0 0.096" rpy="0 0 0"/>
        <limit lower="0" upper="0" effort="10.0" velocity="8.94"/>
        <axis xyz="1 0 0"/>
	</joint>

    <!-- Leg_FL -->>
    <link name="Leg_FL">
      <inertial>
        <origin xyz="0 0 0.5" rpy="0 0 0"/>
        <mass value="1"/>
        <inertia ixx="100"  ixy="0"  ixz="0" iyy="100" iyz="0" izz="100" />
      </inertial>
   
      <visual>
        <origin xyz="-0.5588 0.2032 0" rpy="0 0 0" />
        <geometry>
          <box size="0.3048 0.127 0.1143" />
        </geometry>
        <material name="Cyan">
          <color rgba="0 1.0 1.0 1.0"/>
        </material>
      </visual>
   
      <collision>
        <origin xyz="-0.5588 0.2032 0" rpy="0 0 0" />
        <geometry>
          <box size="0.3048 0.127 0.1143" />
        </geometry>
  </collision>
    </link>
        <gazebo reference="Leg_FL">
        <mu1 value="200.0"/>
        <mu2 value="100.0"/>
        <kp value="10000000.0" />
        <kd value="1.0" />
        <material>Gazebo/Grey</material>
    </gazebo>
    <joint name="Chassie_Leg_FL_Joint" type="continuous">
    	<parent link="base_link"/>
    	<child link="Leg_FL"/>
        <origin xyz="0 0 0.096" rpy="0 0 0"/>
        <limit lower="0" upper="0" effort="10.0" velocity="8.94"/>
        <axis xyz="1 0 0"/>
	</joint>

    <!-- Leg_RR -->>
    <link name="Leg_RR">
      <inertial>
        <origin xyz="0 0 0.5" rpy="0 0 0"/>
        <mass value="1"/>
        <inertia ixx="100"  ixy="0"  ixz="0" iyy="100" iyz="0" izz="100" />
      </inertial>
   
      <visual>
        <origin xyz="0.5588 -0.2032 0" rpy="0 0 0" />
        <geometry>
          <box size="0.3048 0.127 0.1143" />
        </geometry>
        <material name="Cyan">
          <color rgba="0 1.0 1.0 1.0"/>
        </material>
      </visual>
   
      <collision>
        <origin xyz="0.5588 -0.2032 0" rpy="0 0 0" />
        <geometry>
          <box size="0.3048 0.127 0.1143" />
        </geometry>
  </collision>
    </link>
        <gazebo reference="Leg_RR">
        <mu1 value="200.0"/>
        <mu2 value="100.0"/>
        <kp value="10000000.0" />
        <kd value="1.0" />
        <material>Gazebo/Grey</material>
    </gazebo>
    <joint name="Chassie_Leg_RR_Joint" type="continuous">
    	<parent link="base_link"/>
    	<child link="Leg_RR"/>
        <origin xyz="0 0 0.096" rpy="0 0 0"/>
        <limit lower="0" upper="0" effort="10.0" velocity="8.94"/>
        <axis xyz="1 0 0"/>
	</joint>

    <!-- Leg_RL -->>
    <link name="Leg_RL">
      <inertial>
        <origin xyz="0 0 0.5" rpy="0 0 0"/>
        <mass value="1"/>
        <inertia ixx="100"  ixy="0"  ixz="0" iyy="100" iyz="0" izz="100" />
      </inertial>
   
      <visual>
        <origin xyz="-0.5588 -0.2032 0" rpy="0 0 0" />
        <geometry>
          <box size="0.3048 0.127 0.1143" />
        </geometry>
        <material name="Cyan">
          <color rgba="0 1.0 1.0 1.0"/>
        </material>
      </visual>
   
      <collision>
        <origin xyz="-0.5588 -0.2032 0" rpy="0 0 0" />
        <geometry>
          <box size="0.3048 0.127 0.1143" />
        </geometry>
  </collision>
    </link>
        <gazebo reference="Leg_RL">
        <mu1 value="200.0"/>
        <mu2 value="100.0"/>
        <kp value="10000000.0" />
        <kd value="1.0" />
        <material>Gazebo/Grey</material>
    </gazebo>
    <joint name="Chassie_Leg_RL_Joint" type="continuous">
    	<parent link="base_link"/>
    	<child link="Leg_RL"/>
        <origin xyz="0 0 0.096" rpy="0 0 0"/>
        <limit lower="0" upper="0" effort="10.0" velocity="8.94"/>
        <axis xyz="1 0 0"/>
	</joint>

    <!-- Wheel_FR -->
    <link name="Wheel_FR">
 	    <inertial>
            <origin xyz="0 0 0.0362" rpy="0 0 0"/>
            <mass value="0.2" />
            <inertia ixx="0.000220439071667" ixy="0.0" ixz="0.0" iyy="0.000220439071667" iyz="0.0" izz="0.00026615281"/>
        </inertial>
        <collision>
            <origin xyz="0.7588 0.2032 0" rpy="0 0 0" />
            <geometry>
                <cylinder radius="0.508" length="0.254"/>
            </geometry>
        </collision>
        <visual>
            <origin xyz="0.7588 0.2032 0" rpy="0 0 0" />
            <geometry>
                <cylinder radius="0.508" length="0.254"/>
            </geometry>
            <material name="blue"/>
        </visual>
	</link>
    <!-- This is for color and physical properties in Gazebo, color won't work with the material tag in gazebo
    only for URDF coloring -->
    <gazebo reference="Wheel_FR">
        <mu1 value="200.0"/>
        <mu2 value="100.0"/>
        <kp value="10000000.0" />
        <kd value="1.0" />
        <material>Gazebo/Grey</material>
    </gazebo>
    <joint name="Chassie_Wheel_FR_Joint" type="continuous">
    	<parent link="Leg_FR"/>
    	<child link="Wheel_FR"/>
        <origin xyz="0 0 0.096" rpy="0 0 0"/>
        <limit lower="0" upper="0" effort="10.0" velocity="8.94"/>
        <axis xyz="1 0 0"/>
	</joint>

    <!-- Wheel_FL -->
    <link name="Wheel_FL">
 	    <inertial>
            <origin xyz="0 0 0.0362" rpy="0 0 0"/>
            <mass value="0.2" />
            <inertia ixx="0.000220439071667" ixy="0.0" ixz="0.0" iyy="0.000220439071667" iyz="0.0" izz="0.00026615281"/>
        </inertial>
        <collision>
            <origin xyz="-0.7588 0.2032 0" rpy="0 0 0" />
            <geometry>
                <cylinder radius="0.508" length="0.254"/>
            </geometry>
        </collision>
        <visual>
            <origin xyz="-0.7588 0.2032 0" rpy="0 0 0" />
            <geometry>
                <cylinder radius="0.508" length="0.254"/>
            </geometry>
            <material name="blue"/>
        </visual>
	</link>
    <!-- This is for color and physical properties in Gazebo, color won't work with the material tag in gazebo
    only for URDF coloring -->
    <gazebo reference="Wheel_FL">
        <mu1 value="200.0"/>
        <mu2 value="100.0"/>
        <kp value="10000000.0" />
        <kd value="1.0" />
        <material>Gazebo/Grey</material>
    </gazebo>
    <joint name="Chassie_Wheel_FL_Joint" type="continuous">
    	<parent link="Leg_FL"/>
    	<child link="Wheel_FL"/>
        <origin xyz="0 0 0.096" rpy="0 0 0"/>
        <limit lower="0" upper="0" effort="10.0" velocity="8.94"/>
        <axis xyz="1 0 0"/>
	</joint>
    <transmission name="fl_trans">
        <type>transmission_interface/SimpleTransmission</type>
        <actuator name="Chassie_Wheel_FL_motor">
            <mechanicalReduction>1</mechanicalReduction>
        </actuator>
        <joint name="Chassie_Wheel_FL_Joint">
            <hardwareInterface>hardware_interface/EffortJointInterface</hardwareInterface>
        </joint>
    </transmission>

    <!-- Wheel_RR-->
    <link name="Wheel_RR">
 	    <inertial>
            <origin xyz="0 0 0.0362" rpy="0 0 0"/>
            <mass value="0.2" />
            <inertia ixx="0.000220439071667" ixy="0.0" ixz="0.0" iyy="0.000220439071667" iyz="0.0" izz="0.00026615281"/>
        </inertial>
        <collision>
            <origin xyz="0.7588 -0.2032 0" rpy="0 0 0" />
            <geometry>
                <cylinder radius="0.508" length="0.254"/>
            </geometry>
        </collision>
        <visual>
            <origin xyz="0.7588 -0.2032 0" rpy="0 0 0" />
            <geometry>
                <cylinder radius="0.508" length="0.254"/>
            </geometry>
            <material name="blue"/>
        </visual>
	</link>
    <!-- This is for color and physical properties in Gazebo, color won't work with the material tag in gazebo
    only for URDF coloring -->
    <gazebo reference="Wheel_RR">
        <mu1 value="200.0"/>
        <mu2 value="100.0"/>
        <kp value="10000000.0" />
        <kd value="1.0" />
        <material>Gazebo/Grey</material>
    </gazebo>
    <joint name="Chassie_Wheel_RR_Joint" type="continuous">
    	<parent link="Leg_RR"/>
    	<child link="Wheel_RR"/>
        <origin xyz="0 0 0.096" rpy="0 0 0"/>
        <limit lower="0" upper="0" effort="10.0" velocity="8.94"/>
        <axis xyz="1 0 0"/>
	</joint>
    <transmission name="rr_trans">
        <type>transmission_interface/SimpleTransmission</type>
        <actuator name="Chassie_Wheel_RR_motor">
            <mechanicalReduction>1</mechanicalReduction>
        </actuator>
        <joint name="Chassie_Wheel_RR_Joint">
            <hardwareInterface>hardware_interface/EffortJointInterface</hardwareInterface>
        </joint>
    </transmission>

    <!-- Wheel_RL-->
    <link name="Wheel_RL">
 	    <inertial>
            <origin xyz="0 0 0.0362" rpy="0 0 0"/>
            <mass value="0.2" />
            <inertia ixx="0.000220439071667" ixy="0.0" ixz="0.0" iyy="0.000220439071667" iyz="0.0" izz="0.00026615281"/>
        </inertial>
        <collision>
            <origin xyz="-0.7588 -0.2032 0" rpy="0 0 0" />
            <geometry>
                <cylinder radius="0.508" length="0.254"/>
            </geometry>
        </collision>
        <visual>
            <origin xyz="-0.7588 -0.2032 0" rpy="0 0 0" />
            <geometry>
                <cylinder radius="0.508" length="0.254"/>
            </geometry>
            <material name="blue"/>
        </visual>
	</link>
    <!-- This is for color and physical properties in Gazebo, color won't work with the material tag in gazebo
    only for URDF coloring -->
    <gazebo reference="Wheel_RL">
        <mu1 value="200.0"/>
        <mu2 value="100.0"/>
        <kp value="10000000.0" />
        <kd value="1.0" />
        <material>Gazebo/Grey</material>
    </gazebo>
    <joint name="Chassie_Wheel_RL_Joint" type="continuous">
    	<parent link="Leg_RL"/>
    	<child link="Wheel_RL"/>
        <origin xyz="0 0 0.096" rpy="0 0 0"/>
        <limit lower="0" upper="0" effort="10.0" velocity="8.94"/>
        <axis xyz="1 0 0"/>
	</joint>    
    <transmission name="rl_trans">
        <type>transmission_interface/SimpleTransmission</type>
        <actuator name="Chassie_Wheel_RL_motor">
            <mechanicalReduction>1</mechanicalReduction>
        </actuator>
        <joint name="Chassie_Wheel_RL_Joint">
            <hardwareInterface>hardware_interface/EffortJointInterface</hardwareInterface>
        </joint>
    </transmission>

</robot>