<robot name="rover">

    <material name="blue">
        <color rgba="0 0 0.8 1"/>
    </material>
    <material name="red">
        <color rgba="0.8 0 0 1"/>
    </material>
    <material name="green">
        <color rgba="0 0.8 0 1"/>
    </material>
    <material name="purple">
        <color rgba="0.8 0 0.8 1"/>
    </material>

    <gazebo>
        <plugin name="gazebo_ros_control" filename="libgazebo_ros_control.so">
        </plugin>
    </gazebo>

	<!-- chassie -->
    <link name="base_link">
 	    <inertial>
            <origin xyz="0 0 0" rpy="0 0 0"/>
            <mass value="0.2" />
            <inertia ixx="0.0005726" ixy="0.0" ixz="0.0" iyy="0.0005726" iyz="0.0" izz="0.0002704"/>
        </inertial>
        <collision>
            <origin rpy="0.0 0 0" xyz="0 0 0"/>
            <geometry>
                <box size="1.5 0.5 .005"/>
            </geometry>
        </collision>
        <visual>
            <origin rpy="0.0 0 0" xyz="0 0 0"/>
            <geometry>
                <box size="1.5 0.5 .005"/>
            </geometry>
            <material name="red"/>
        </visual>
	</link>
    <gazebo reference="base_link">
        <kp>1000000.0</kp>
        <kd>1000000.0</kd>
        <mu1>10.0</mu1>
        <mu2>10.0</mu2>
        <material>Gazebo/Red</material>
    </gazebo>

    <!-- Wheel_FR -->
    <link name="Wheel_FR">
 	    <inertial>
            <origin xyz="0 0 0.0362" rpy="0 0 0"/>
            <mass value="0.2" />
            <inertia ixx="0.000220439071667" ixy="0.0" ixz="0.0" iyy="0.000220439071667" iyz="0.0" izz="0.00026615281"/>
        </inertial>
        <collision>
            <origin xyz="0 0 0.0362" rpy="0 0 0"/>
            <geometry>
                <cylinder radius="0.4572" length="0.254"/>
            </geometry>
        </collision>
        <visual>
            <origin xyz="0 0 0.0362" rpy="0 0 0"/>
            <geometry>
                <cylinder radius="0.4572" length="0.254"/>
            </geometry>
            <material name="blue"/>
        </visual>
	</link>
    <!-- This is for color and physical properties in Gazebo, color won't work with the material tag in gazebo
    only for URDF coloring -->
    <gazebo reference="Wheel_FR">
        <mu1 value="200.0"/>
        <mu2 value="100.0"/>
        <kp value="10000000.0" />
        <kd value="1.0" />
        <material>Gazebo/Grey</material>
    </gazebo>
    <joint name="Chassie_Wheel_FR_Joint" type="continuous">
    	<parent link="base_link"/>
    	<child link="Wheel_FR"/>
        <origin xyz="0 0 0.096" rpy="0 0 0"/>
        <limit lower="0" upper="0" effort="10.0" velocity="8.94"/>
        <axis xyz="1 0 0"/>
	</joint>
    <transmission name="fr_trans">
        <type>transmission_interface/SimpleTransmission</type>
        <actuator name="Chassie_Wheel_FR_motor">
            <mechanicalReduction>1</mechanicalReduction>
        </actuator>
        <joint name="Chassie_Wheel_FR_Joint">
            <hardwareInterface>hardware_interface/EffortJointInterface</hardwareInterface>
        </joint>
    </transmission>

    <!-- Wheel_FL -->
    <link name="Wheel_FL">
 	    <inertial>
            <origin xyz="0 0 0.0362" rpy="0 0 0"/>
            <mass value="0.2" />
            <inertia ixx="0.000220439071667" ixy="0.0" ixz="0.0" iyy="0.000220439071667" iyz="0.0" izz="0.00026615281"/>
        </inertial>
        <collision>
            <origin xyz="0 0 0.0362" rpy="0 0 0"/>
            <geometry>
                <cylinder radius="0.4572" length="0.254"/>
            </geometry>
        </collision>
        <visual>
            <origin xyz="0 0 0.0362" rpy="0 0 0"/>
            <geometry>
                <cylinder radius="0.4572" length="0.254"/>
            </geometry>
            <material name="blue"/>
        </visual>
	</link>
    <!-- This is for color and physical properties in Gazebo, color won't work with the material tag in gazebo
    only for URDF coloring -->
    <gazebo reference="Wheel_FL">
        <mu1 value="200.0"/>
        <mu2 value="100.0"/>
        <kp value="10000000.0" />
        <kd value="1.0" />
        <material>Gazebo/Grey</material>
    </gazebo>
    <joint name="Chassie_Wheel_FL_Joint" type="continuous">
    	<parent link="base_link"/>
    	<child link="Wheel_FL"/>
        <origin xyz="0 0 0.096" rpy="0 0 0"/>
        <limit lower="0" upper="0" effort="10.0" velocity="8.94"/>
        <axis xyz="1 0 0"/>
	</joint>
    <transmission name="fl_trans">
        <type>transmission_interface/SimpleTransmission</type>
        <actuator name="Chassie_Wheel_FL_motor">
            <mechanicalReduction>1</mechanicalReduction>
        </actuator>
        <joint name="Chassie_Wheel_FL_Joint">
            <hardwareInterface>hardware_interface/EffortJointInterface</hardwareInterface>
        </joint>
    </transmission>

    <!-- Wheel_RR-->
    <link name="Wheel_RR">
 	    <inertial>
            <origin xyz="0 0 0.0362" rpy="0 0 0"/>
            <mass value="0.2" />
            <inertia ixx="0.000220439071667" ixy="0.0" ixz="0.0" iyy="0.000220439071667" iyz="0.0" izz="0.00026615281"/>
        </inertial>
        <collision>
            <origin xyz="0 0 0.0362" rpy="0 0 0"/>
            <geometry>
                <cylinder radius="0.4572" length="0.254"/>
            </geometry>
        </collision>
        <visual>
            <origin xyz="0 0 0.0362" rpy="0 0 0"/>
            <geometry>
                <cylinder radius="0.4572" length="0.254"/>
            </geometry>
            <material name="blue"/>
        </visual>
	</link>
    <!-- This is for color and physical properties in Gazebo, color won't work with the material tag in gazebo
    only for URDF coloring -->
    <gazebo reference="Wheel_RR">
        <mu1 value="200.0"/>
        <mu2 value="100.0"/>
        <kp value="10000000.0" />
        <kd value="1.0" />
        <material>Gazebo/Grey</material>
    </gazebo>
    <joint name="Chassie_Wheel_RR_Joint" type="continuous">
    	<parent link="base_link"/>
    	<child link="Wheel_RR"/>
        <origin xyz="0 0 0.096" rpy="0 0 0"/>
        <limit lower="0" upper="0" effort="10.0" velocity="8.94"/>
        <axis xyz="1 0 0"/>
	</joint>
    <transmission name="rr_trans">
        <type>transmission_interface/SimpleTransmission</type>
        <actuator name="Chassie_Wheel_RR_motor">
            <mechanicalReduction>1</mechanicalReduction>
        </actuator>
        <joint name="Chassie_Wheel_RR_Joint">
            <hardwareInterface>hardware_interface/EffortJointInterface</hardwareInterface>
        </joint>
    </transmission>

    <!-- Wheel_RL-->
    <link name="Wheel_RL">
 	    <inertial>
            <origin xyz="0 0 0.0362" rpy="0 0 0"/>
            <mass value="0.2" />
            <inertia ixx="0.000220439071667" ixy="0.0" ixz="0.0" iyy="0.000220439071667" iyz="0.0" izz="0.00026615281"/>
        </inertial>
        <collision>
            <origin xyz="0 0 0.0362" rpy="0 0 0"/>
            <geometry>
                <cylinder radius="0.4572" length="0.254"/>
            </geometry>
        </collision>
        <visual>
            <origin xyz="0 0 0.0362" rpy="0 0 0"/>
            <geometry>
                <cylinder radius="0.4572" length="0.254"/>
            </geometry>
            <material name="blue"/>
        </visual>
	</link>
    <!-- This is for color and physical properties in Gazebo, color won't work with the material tag in gazebo
    only for URDF coloring -->
    <gazebo reference="Wheel_RL">
        <mu1 value="200.0"/>
        <mu2 value="100.0"/>
        <kp value="10000000.0" />
        <kd value="1.0" />
        <material>Gazebo/Grey</material>
    </gazebo>
    <joint name="Chassie_Wheel_RL_Joint" type="continuous">
    	<parent link="base_link"/>
    	<child link="Wheel_RL"/>
        <origin xyz="0 0 0.096" rpy="0 0 0"/>
        <limit lower="0" upper="0" effort="10.0" velocity="8.94"/>
        <axis xyz="1 0 0"/>
	</joint>    
    <transmission name="rl_trans">
        <type>transmission_interface/SimpleTransmission</type>
        <actuator name="Chassie_Wheel_RL_motor">
            <mechanicalReduction>1</mechanicalReduction>
        </actuator>
        <joint name="Chassie_Wheel_RL_Joint">
            <hardwareInterface>hardware_interface/EffortJointInterface</hardwareInterface>
        </joint>
    </transmission>

</robot>